{"uid":"432c3988511100b6","name":"test_with_bug","fullName":"tests.pytest.test_pytest_xfail#test_with_bug","historyId":"fb30392daae1117f9ea61a430455c804","time":{"start":1747832207368,"stop":1747832207369,"duration":1},"status":"skipped","statusMessage":"XFAIL Найден баг в приложении, из-за которого тест падает с ошибкой\n\nAssertionError: assert 1 == 2","statusTrace":"@pytest.mark.xfail(reason='Найден баг в приложении, из-за которого тест падает с ошибкой')\n    def test_with_bug():\n>       assert 1 == 2\nE       assert 1 == 2\n\ntests/pytest/test_pytest_xfail.py:5: AssertionError","flaky":false,"newFailed":false,"newBroken":false,"newPassed":false,"retriesCount":0,"retriesStatusChange":false,"beforeStages":[{"name":"_session_faker","time":{"start":1747832199374,"stop":1747832199375,"duration":1},"status":"passed","steps":[],"attachments":[],"parameters":[],"shouldDisplayMessage":false,"attachmentsCount":0,"attachmentStep":false,"stepsCount":0,"hasContent":false}],"afterStages":[],"labels":[{"name":"tag","value":"@pytest.mark.xfail(reason='Найден баг в приложении, из-за которого тест падает с ошибкой')"},{"name":"parentSuite","value":"tests.pytest"},{"name":"suite","value":"test_pytest_xfail"},{"name":"host","value":"MacBook-Air-Rik.local"},{"name":"thread","value":"40561-MainThread"},{"name":"framework","value":"pytest"},{"name":"language","value":"cpython3"},{"name":"package","value":"tests.pytest.test_pytest_xfail"},{"name":"resultFormat","value":"allure2"}],"parameters":[],"links":[],"hidden":false,"retry":false,"extra":{"severity":"normal","retries":[],"categories":[],"tags":["@pytest.mark.xfail(reason='Найден баг в приложении, из-за которого тест падает с ошибкой')"]},"source":"432c3988511100b6.json","parameterValues":[]}